<!DOCTYPE html>
<html lang="en">

<head>
	<meta charset="UTF-8">
	<meta name="viewport" content="width=device-width, initial-scale=1.0">
	<title>34_catch_method</title>
</head>

<body style="font-family: sans-serif; margin: 20px;">
	<h1>34_catch_method</h1>

	<p>In JavaScript, the .catch() method is used in combination with promises to handle errors that might occur during the execution of an asynchronous operation.</p>

	<p>When a promise is rejected (an error occurs), the control is transferred to the .catch() block where you can handle the error gracefully.</p>


<script>
		// Function that returns a promise
		function asyncOperation() {
			return new Promise((resolve, reject) => {
				// Simulating an asynchronous operation
				setTimeout(() => {
					// Simulating an error condition
					const error = new Error('Something Went Wrong');
					reject(error);
				}, 2000);
			});
		}

		// Using the async operation and handling errors with .catch()
		asyncOperation()
			.then(result => {
				console.log('Async Operation Completed Successfully:', result);
			})
			.catch(error => {
				console.error('Error Occurred During Async Operation:', error.message);
			});

	</script>

</body>

</html>